#VRML_SIM R2022a utf8
WorldInfo {
}
Viewpoint {
  orientation -0.0885405801330455 -0.0022895712133285165 0.9960699390772533 2.8685327128547025
  position 0.964036745395286 -4.989239959164528 5.254687415970274
}
TexturedBackground {
  texture "mars"
}
TexturedBackgroundLight {
  luminosity 2
}
UnevenTerrain {
  appearance SandyGround {
    colorOverride 0.55 0.55 0.4
    textureTransform TextureTransform {
      scale 50 50
    }
  }
}
Robot {
  translation -5.59408993458272 -2.0391345187975602 3.141097231519541
  rotation 0.07768055366715754 0.034481993016549695 -0.9963818162429353 0.6635570520136334
  children [
    DEF body Shape {
      appearance HammeredCopper {
      }
      geometry Box {
        size 0.7 0.5 0.2
      }
    }
    Solid {
      translation 0 0 0.19
      children [
        DEF panel Shape {
          appearance SolarCell {
          }
          geometry Box {
            size 0.8 0.5 0.01
          }
        }
        Solid {
          translation 0.3 -0.19 -0.05
          children [
            Shape {
              appearance Copper {
              }
              geometry Cylinder {
                height 0.1
                radius 0.02
              }
            }
          ]
          name "solar_panel_support1"
        }
        Solid {
          translation 0.3 0.19 -0.05
          children [
            Shape {
              appearance Copper {
              }
              geometry Cylinder {
                height 0.1
                radius 0.02
              }
            }
          ]
          name "solar_panel_support2"
        }
        Solid {
          translation -0.3 0.19 -0.05
          children [
            Shape {
              appearance Copper {
              }
              geometry Cylinder {
                height 0.1
                radius 0.02
              }
            }
          ]
          name "solar_panel_support3"
        }
        Solid {
          translation -0.3 -0.19 -0.05
          children [
            Shape {
              appearance Copper {
              }
              geometry Cylinder {
                height 0.1
                radius 0.02
              }
            }
          ]
          name "solar_panel_support4"
        }
      ]
      name "solar_panel"
    }
    Solid {
      translation -0.18 -0.24 0
      children [
        Solid {
          translation -0.00017766252744422228 -0.017340268664742475 0.05993637531167906
          rotation -0.9999999929357695 8.124469320562993e-05 -8.676267159571073e-05 1.5708626067521982
          children [
            DEF cylinder1 Shape {
              appearance DamascusSteel {
              }
              geometry Cylinder {
                height 0.09
                radius 0.02
              }
            }
            Solid {
              translation 0 0 -0.05
              children [
                DEF sphere1 Shape {
                  appearance BrushedSteel {
                  }
                  geometry Sphere {
                    radius 0.02
                  }
                }
                Solid {
                  translation 0 0.1 1.79608e-07
                  rotation -1 0 0 -1.5707953071795862
                  children [
                    DEF cylinder2 Shape {
                      appearance BrushedSteel {
                      }
                      geometry Cylinder {
                        height 0.2
                        radius 0.02
                      }
                    }
                    Solid {
                      translation 0 0 -0.11
                      children [
                        DEF sphere1 Shape {
                          appearance BrushedSteel {
                          }
                          geometry Sphere {
                            radius 0.02
                          }
                        }
                        Solid {
                          translation 0 -0.03 -9.99999e-08
                          rotation 1 0 0 1.5708
                          children [
                            DEF cylinder3 Shape {
                              appearance BrushedSteel {
                              }
                              geometry Cylinder {
                                height 0.06
                                radius 0.02
                              }
                            }
                            HingeJoint {
                              jointParameters HingeJointParameters {
                                position 148.2912455686735
                                axis 0 0 1
                                anchor -9.51224e-05 0.00113507 0.0800056
                              }
                              device [
                                RotationalMotor {
                                  name "wheel1_left"
                                }
                              ]
                              endPoint Solid {
                                translation -0.0016499563756801406 0.0016489897025854239 0.07995424362107062
                                rotation 4.719878082063614e-06 6.89537436329598e-07 0.9999999999886238 3.789862853714651
                                children [
                                  DEF wheel Shape {
                                    appearance DamascusSteel {
                                    }
                                    geometry Cylinder {
                                      height 0.15
                                      radius 0.15
                                    }
                                  }
                                ]
                                boundingObject USE wheel
                                physics Physics {
                                  mass 1
                                }
                                linearVelocity 3.923986988464631e-06 -2.128249372208312e-05 -1.2390289365384909e-06
                                angularVelocity 3.458231708678487e-06 4.217361449106808e-06 3.0019967847838e-06
                              }
                            }
                          ]
                          boundingObject USE cylinder3
                          physics DEF phy1 Physics {
                            mass 1
                          }
                        }
                      ]
                      name "solid(1)"
                      boundingObject USE sphere1
                      physics USE phy1
                    }
                  ]
                  boundingObject USE cylinder2
                  physics USE phy1
                }
              ]
              boundingObject USE sphere1
              physics USE phy1
            }
          ]
          boundingObject USE cylinder1
          physics USE phy1
        }
      ]
      name "wheel1_left_system"
      physics DEF phy1 Physics {
        mass 1
      }
    }
    Solid {
      translation 0.18 -0.24 0
      children [
        Solid {
          translation -0.0001757815149209252 -0.017333744024692788 0.0600545153188472
          rotation -0.9999999930027248 7.374603208071159e-05 -9.249904417794078e-05 1.5708786387286822
          children [
            DEF cylinder1 Shape {
              appearance DamascusSteel {
              }
              geometry Cylinder {
                height 0.09
                radius 0.02
              }
            }
            Solid {
              translation 0 0 -0.05
              children [
                DEF sphere1 Shape {
                  appearance BrushedSteel {
                  }
                  geometry Sphere {
                    radius 0.02
                  }
                }
                Solid {
                  translation 0 0.1 1.79608e-07
                  rotation -1 0 0 -1.5707953071795862
                  children [
                    DEF cylinder2 Shape {
                      appearance BrushedSteel {
                      }
                      geometry Cylinder {
                        height 0.2
                        radius 0.02
                      }
                    }
                    Solid {
                      translation 0 0 -0.11
                      children [
                        DEF sphere1 Shape {
                          appearance BrushedSteel {
                          }
                          geometry Sphere {
                            radius 0.02
                          }
                        }
                        Solid {
                          translation 0 -0.03 -9.99999e-08
                          rotation 1 0 0 1.5708
                          children [
                            DEF cylinder3 Shape {
                              appearance BrushedSteel {
                              }
                              geometry Cylinder {
                                height 0.06
                                radius 0.02
                              }
                            }
                            HingeJoint {
                              jointParameters HingeJointParameters {
                                position -163.50268155805293
                                axis 0 0 1
                                anchor 0.000341778 0.000558794 0.0800055
                              }
                              device [
                                RotationalMotor {
                                  name "wheel2_left"
                                }
                              ]
                              endPoint Solid {
                                translation -0.0003001304588939301 -8.070754563645698e-05 0.07995173580166282
                                rotation -2.9754584797041135e-05 1.4807634926167253e-05 -0.9999999994476992 0.1291091988908821
                                children [
                                  DEF wheel Shape {
                                    appearance DamascusSteel {
                                    }
                                    geometry Cylinder {
                                      height 0.15
                                      radius 0.15
                                    }
                                  }
                                ]
                                boundingObject USE wheel
                                physics Physics {
                                  mass 1
                                }
                                linearVelocity 4.536831642312236e-06 -2.048753828948164e-05 -1.1806037811084247e-06
                                angularVelocity 3.083162557692585e-06 3.736356978693004e-06 2.9772019708846846e-06
                              }
                            }
                          ]
                          boundingObject USE cylinder3
                          physics DEF phy1 Physics {
                            mass 1
                          }
                        }
                      ]
                      name "solid(1)"
                      boundingObject USE sphere1
                      physics USE phy1
                    }
                  ]
                  boundingObject USE cylinder2
                  physics USE phy1
                }
              ]
              boundingObject USE sphere1
              physics USE phy1
            }
          ]
          boundingObject USE cylinder1
          physics USE phy1
        }
      ]
      name "wheel2_left_system"
      physics USE phy1
    }
    Solid {
      translation -0.18 0.24 0
      children [
        Solid {
          translation -0.000177663 0.0173403 0.0599364
          rotation -0.9999999929357695 8.124469320562993e-05 -8.676267159571073e-05 1.5708626067521982
          children [
            DEF cylinder1 Shape {
              appearance DamascusSteel {
              }
              geometry Cylinder {
                height 0.09
                radius 0.02
              }
            }
            Solid {
              translation 0 0 0.05
              children [
                DEF sphere1 Shape {
                  appearance BrushedSteel {
                  }
                  geometry Sphere {
                    radius 0.02
                  }
                }
                Solid {
                  translation 0 0.1 1.79608e-07
                  rotation -1 0 0 -1.5707953071795862
                  children [
                    DEF cylinder2 Shape {
                      appearance BrushedSteel {
                      }
                      geometry Cylinder {
                        height 0.2
                        radius 0.02
                      }
                    }
                    Solid {
                      translation 0 0 -0.11
                      children [
                        DEF sphere1 Shape {
                          appearance BrushedSteel {
                          }
                          geometry Sphere {
                            radius 0.02
                          }
                        }
                        Solid {
                          translation 0 0.03 -9.99999e-08
                          rotation 1 0 0 1.5708
                          children [
                            DEF cylinder3 Shape {
                              appearance BrushedSteel {
                              }
                              geometry Cylinder {
                                height 0.06
                                radius 0.02
                              }
                            }
                            HingeJoint {
                              jointParameters HingeJointParameters {
                                position 188.07748923203027
                                axis 0 0 1
                                anchor 0.00237208 0.000614304 -0.0799754
                              }
                              device [
                                RotationalMotor {
                                  name "wheel1_right"
                                }
                              ]
                              endPoint Solid {
                                translation 0.0008025202755807077 0.000582914063496262 -0.07997536572404963
                                rotation 0.5301802924626879 -0.8478849317241868 6.2649615954113114e-06 3.1415965973396074
                                children [
                                  DEF wheel Shape {
                                    appearance DamascusSteel {
                                    }
                                    geometry Cylinder {
                                      height 0.15
                                      radius 0.15
                                    }
                                  }
                                ]
                                boundingObject USE wheel
                                physics Physics {
                                  mass 1
                                }
                                linearVelocity 2.093967765821168e-06 -1.985285680155075e-05 -1.1285250752734706e-06
                                angularVelocity 2.890716096907218e-06 3.489602085703213e-06 2.9646075316350188e-06
                              }
                            }
                          ]
                          boundingObject USE cylinder3
                          physics DEF phy1 Physics {
                            mass 1
                          }
                        }
                      ]
                      name "solid(1)"
                      boundingObject USE sphere1
                      physics USE phy1
                    }
                  ]
                  boundingObject USE cylinder2
                  physics USE phy1
                }
              ]
              boundingObject USE sphere1
              physics USE phy1
            }
          ]
          boundingObject USE cylinder1
          physics USE phy1
        }
      ]
      name "wheel1_right_system"
      physics DEF phy1 Physics {
        mass 1
      }
    }
    Solid {
      translation 0.18 0.24 0
      children [
        Solid {
          translation -0.000177663 0.0173403 0.0599364
          rotation -0.9999999929357695 8.124469320562993e-05 -8.676267159571073e-05 1.5708626067521982
          children [
            DEF cylinder1 Shape {
              appearance DamascusSteel {
              }
              geometry Cylinder {
                height 0.09
                radius 0.02
              }
            }
            Solid {
              translation 0 0 0.05
              children [
                DEF sphere1 Shape {
                  appearance BrushedSteel {
                  }
                  geometry Sphere {
                    radius 0.02
                  }
                }
                Solid {
                  translation 0 0.1 1.79608e-07
                  rotation -1 0 0 -1.5707953071795862
                  children [
                    DEF cylinder2 Shape {
                      appearance BrushedSteel {
                      }
                      geometry Cylinder {
                        height 0.2
                        radius 0.02
                      }
                    }
                    Solid {
                      translation 0 0 -0.11
                      children [
                        DEF sphere1 Shape {
                          appearance BrushedSteel {
                          }
                          geometry Sphere {
                            radius 0.02
                          }
                        }
                        Solid {
                          translation 0 0.03 -9.99999e-08
                          rotation 1 0 0 1.5708
                          children [
                            DEF cylinder3 Shape {
                              appearance BrushedSteel {
                              }
                              geometry Cylinder {
                                height 0.06
                                radius 0.02
                              }
                            }
                            HingeJoint {
                              jointParameters HingeJointParameters {
                                position 183.8595052773784
                                axis 0 0 1
                                anchor 0.00237208 0.000614304 -0.0799754
                              }
                              device [
                                RotationalMotor {
                                  name "wheel2_right"
                                }
                              ]
                              endPoint Solid {
                                translation 0.0031444796878570564 -0.0007524080321527841 -0.07997536572404963
                                rotation -0.9997874660791507 -0.020616077918127997 -1.5182205679387856e-06 3.1415798734425717
                                children [
                                  DEF wheel Shape {
                                    appearance DamascusSteel {
                                    }
                                    geometry Cylinder {
                                      height 0.15
                                      radius 0.15
                                    }
                                  }
                                ]
                                boundingObject USE wheel
                                physics Physics {
                                  mass 1
                                }
                                linearVelocity 2.709652527037149e-06 -1.9056453737869402e-05 -1.0737295259559381e-06
                                angularVelocity 2.139781180517732e-06 2.5264580870723027e-06 2.915120144293423e-06
                              }
                            }
                          ]
                          boundingObject USE cylinder3
                          physics DEF phy1 Physics {
                            mass 1
                          }
                        }
                      ]
                      name "solid(1)"
                      boundingObject USE sphere1
                      physics USE phy1
                    }
                  ]
                  boundingObject USE cylinder2
                  physics USE phy1
                }
              ]
              boundingObject USE sphere1
              physics USE phy1
            }
          ]
          boundingObject USE cylinder1
          physics USE phy1
        }
      ]
      name "wheel2_right_system"
      physics DEF phy1 Physics {
        mass 1
      }
    }
  ]
  boundingObject USE body
  physics DEF phy Physics {
    mass 1
  }
  controller "my_controller"
  linearVelocity 3.3084325165847875e-06 -2.0169500677396145e-05 -1.1596241602819646e-06
  angularVelocity -3.508286627294435e-09 -2.2230317793023303e-07 2.773887279144025e-06
}
